Workbook

Sheet Synthèse
A1: StudyTune — Tableau de bord de pilotage
A2: Version v1.0.0-rc.9 · Sprint en cours : S6 · Recette et livraison · Mise à jour du 14/09/2026
A3: Périmètre de lecture : le projet a été réalisé par une seule personne ; la répartition de la charge simule l'équipe cible dimensionnée au cadrage. Les dates, versions, anomalies, scénarios de recette et coûts sont réels.
A5: Axe de pilotage | B5: Indicateur | C5: Valeur | D5: Cible | E5: Lecture
A6: Avancement | B6: Priorités Must livrées | C6: =Avancement!$E$16 -> 1 | D6: 1 | E6: Aucune concession sur le périmètre indispensable.
A7: Avancement | B7: Versions publiées | C7: =Données!$B$47 -> 12 | D7: 6 | E7: Un incrément démontrable à chaque jalon.
A8: Délais | B8: Jalons tenus | C8: =Délais!$D$11 -> 0.6 | D8: 0.8 | E8: Deux jalons internes dépassés, aucun jalon contractuel manqué.
A9: Charge | B9: Charge consommée | C9: =Charge!$C$14 -> 74.5 | D9: =Charge!$B$14 -> 72 | E9: Estimation globalement juste, mais mal répartie entre les lots.
A10: Charge | B10: Écart de charge | C10: =Charge!$E$14 -> 0.034722222 | D10: 0.1 | E10: Sous la tolérance de 10 % fixée au cadrage.
A11: Coûts | B11: Exploitation mensuelle | C11: =Coûts!$C$11 -> 14.758333 | D11: =Coûts!$B$11 -> 470 | E11: Budget d'exploitation très surdimensionné au cadrage.
A12: Coûts | B12: Marge brute par abonné | C12: =Coûts!$C$30 -> 0.77074148 | D12: 0.5 | E12: L'erreur d'estimation du coût unitaire sous-évaluait la marge.
A13: Qualité | B13: Cibles qualité atteintes | C13: =Qualité!$D$12 -> 1 | D13: 1 | E13: Seuils de couverture bloquants en intégration continue.
A14: Qualité | B14: Anomalies ouvertes | C14: =Données!$B$46 -> 0 | D14: 0 | E14: Les dix anomalies détectées sont corrigées et rattachées à une version.
A15: Risques | B15: Risques à criticité ≥ 12 | C15: =COUNTIF(Risques!D5:D13,">=12") -> 4 | D15: 2 | E15: Disponibilité de l'équipe et concentration des savoirs restent les points durs.
A17: Trois enseignements de pilotage
A18: • Les exigences non fonctionnelles — sécurité, conformité, mise en production — ont été systématiquement sous-estimées, alors que le périmètre social l'a été à l'excès.
A19: • Le risque de disponibilité de l'équipe figurait au registre de cadrage sans indicateur pour le surveiller : il s'est réalisé et a coûté sept semaines.
A20: • Le budget d'exploitation reposait sur des ordres de grandeur, non sur les grilles tarifaires des fournisseurs : l'écart atteint un facteur dix.
A22: Feuilles : Synthèse · Avancement · Délais · Charge · Coûts · Qualité · Risques · Arbitrages · Données (sources).

Sheet Données
A1: Données source du tableau de bord
A2: Bleu = donnée saisie (source citée en colonne E). Toutes les autres feuilles calculent à partir d'ici.
A4: 1. Cadrage (Bloc 1)
A5: Paramètre | B5: Valeur | C5: Unité | E5: Source
A6: Charge totale estimée | B6: 72 | C6: j/h | E6: Dossier de cadrage — 8 lots
A7: Budget projet | B7: 35000 | C7: € | E7: Dossier de cadrage — enveloppe
A8: Exploitation prévue | B8: 470 | C8: €/mois | E8: Dossier de cadrage — budget d'exploitation
A9: dont APIs IA (Mistral) | B9: 80 | C9: €/mois | E9: Dossier de cadrage
A10: dont APIs IA (musique, 500 gén./mois) | B10: 200 | C10: €/mois | E10: Dossier de cadrage
A11: dont infrastructure | B11: 120 | C11: €/mois | E11: Dossier de cadrage
A12: dont hébergement front (Vercel Pro) | B12: 20 | C12: €/mois | E12: Dossier de cadrage
A13: dont outils et licences | B13: 50 | C13: €/mois | E13: Dossier de cadrage
A14: Volume cible de générations | B14: 500 | C14: gén./mois | E14: Dossier de cadrage
A15: Prix abonnement premium | B15: 4.99 | C15: €/mois | E15: Dossier de cadrage — modèle freemium
A17: 2. Coûts réels d'exploitation
A18: Poste | B18: Valeur | C18: Unité | D18: €/mois | E18: Source
A19: VPS OVH | B19: 10.19 | C19: €/mois | D19: =IF($C$19="€/an",$B$19/12,$B$19) -> 10.19 | E19: Facture OVH — communiqué par le chef de projet
A20: Object Storage OVH (GRA) | B20: 3.95 | C20: €/mois | D20: =IF($C$20="€/an",$B$20/12,$B$20) -> 3.95 | E20: Facture OVH — communiqué par le chef de projet
A21: Nom de domaine | B21: 7.3 | C21: €/an | D21: =IF($C$21="€/an",$B$21/12,$B$21) -> 0.60833333 | E21: Facture registrar — communiqué par le chef de projet
A22: Mistral (fiche, paroles, modération) | B22: 0.01 | C22: €/mois | D22: =IF($C$22="€/an",$B$22/12,$B$22) -> 0.01 | E22: Facturation à l'usage depuis le 14/09 — 0,01 € constaté sur 43 appels
A23: Hébergement front | B23: 0 | C23: €/mois | D23: =IF($C$23="€/an",$B$23/12,$B$23) -> 0 | E23: Servi par le VPS (arbitrage Vercel → VPS)
A24: Total exploitation réelle | D24: =SUM(D19:D23) -> 14.758333
A26: 3. Tarification des générations
A27: Paramètre | B27: Valeur | C27: Unité | E27: Source
A28: Prix du pack Kie.ai | B28: 5 | C28: $ | E28: Grille tarifaire Kie.ai — communiquée par le chef de projet
A29: Tokens par pack | B29: 1000 | C29: tokens | E29: Grille tarifaire Kie.ai
A30: Tokens par génération musicale | B30: 12 | C30: tokens | E30: Mesuré en production (dossier Bloc 4)
A31: Taux de change retenu | B31: 0.92 | C31: €/$ | E31: Hypothèse de conversion — à réactualiser
A32: Générations mesurées par abonné | B32: 20 | C32: gén./mois | E32: Hypothèse de modélisation de la marge
A33: Générations du relevé de consommation texte | B33: 10 | C33: gén. | E33: Relevé du 14/09 : 43 appels API, ~10 générations complètes
A34: Marge de prudence sur le coût texte | B34: 2 | C34: × | E34: Le coût texte dépend de la longueur du cours : relevé doublé par prudence
A35: Coût d'une génération ($) | B35: =Données!$B$28/Données!$B$29*Données!$B$30 -> 0.06 | E35: Calcul : prix du pack ÷ tokens par pack × tokens par génération
A37: 4. Qualité (relevé au 14/09/2026)
A38: Indicateur | B38: Valeur | C38: Unité | E38: Source
A39: Tests unitaires API | B39: 122 | C39: cas | E39: Comptage des cas dans api/src/**/*.spec.ts
A40: Tests unitaires client | B40: 46 | C40: cas | E40: Comptage des cas dans client/src/**/*.spec.ts
A41: Tests end-to-end | B41: 9 | C41: cas | E41: Comptage des cas dans api/test
A42: Seuil de couverture — instructions | B42: 0.81 | C42: % | E42: api/package.json — coverageThreshold, bloquant en CI
A43: Seuil de couverture — branches | B43: 0.63 | C43: % | E43: api/package.json — coverageThreshold, bloquant en CI
A44: Scénarios de recette | B44: 37 | C44: scénarios | E44: docs/cahier-recettes.md
...

Sheet Charge
A1: Charge : estimé vs réalisé
A2: Périmètre S0 à S6 (hors backlog v1.1). Estimations de l'équipe cible ; jours réellement consommés relevés en fin de sprint.
A4: Par lot
A5: Lot | B5: Estimé (j/h) | C5: Réalisé (j/h) | D5: Écart (j/h) | E5: Écart (%) | F5: Commentaire
A6: L1 · Import du cours | B6: 8 | C6: 7 | D6: =C6-B6 -> -1 | E6: =IF(B6=0,"",D6/B6) -> -0.125 | F6: Conforme.
A7: L2 · Fiche & paroles IA | B7: 10 | C7: 10 | D7: =C7-B7 -> 0 | E7: =IF(B7=0,"",D7/B7) -> 0 | F7: Cache anti-redondance livré en avance de phase.
A8: L3 · Musique & lecteur | B8: 12 | C8: 14 | D8: =C8-B8 -> 2 | E8: =IF(B8=0,"",D8/B8) -> 0.16666667 | F8: Webhook du fournisseur musical et karaoké sous-estimés (anomalies B-03, B-04).
A9: L4 · Compte, RGPD & abonnement | B9: 8 | C9: 10 | D9: =C9-B9 -> 2 | E9: =IF(B9=0,"",D9/B9) -> 0.25 | F9: Exigences RGPD mineurs et rotation des jetons sous-estimées ; Stripe déprogrammé.
A10: L5 · Bibliothèque & playlists | B10: 6 | C10: 5.5 | D10: =C10-B10 -> -0.5 | E10: =IF(B10=0,"",D10/B10) -> -0.083333333 | F10: Conforme.
A11: L6 · Social | B11: 10 | C11: 6 | D11: =C11-B11 -> -4 | E11: =IF(B11=0,"",D11/B11) -> -0.4 | F11: Périmètre social réduit : fonctionnalités Could livrées au minimum.
A12: L7 · Socle technique & DevOps | B12: 8 | C12: 11.5 | D12: =C12-B12 -> 3.5 | E12: =IF(B12=0,"",D12/B12) -> 0.4375 | F12: Mise en production et supervision sous-estimées (anomalie B-10).
A13: L8 · Pilotage | B13: 10 | C13: 10.5 | D13: =C13-B13 -> 0.5 | E13: =IF(B13=0,"",D13/B13) -> 0.05 | F13: Pilotage et documentation légèrement sous-estimés.
A14: TOTAL | B14: =SUM(B6:B13) -> 72 | C14: =SUM(C6:C13) -> 74.5 | D14: =C14-B14 -> 2.5 | E14: =D14/B14 -> 0.034722222 | F14: Estimation globalement juste, mais mal répartie entre les lots.
A16: Par membre de l'équipe
A17: Membre | B17: Estimé (j/h) | C17: Réalisé (j/h) | D17: Écart (j/h) | E17: Écart (%) | F17: Rôle
A18: Raphaël | B18: 22.5 | C18: 26 | D18: =C18-B18 -> 3.5 | E18: =D18/B18 -> 0.15555556 | F18: Chef de projet / tech lead
A19: Hugo | B19: 15 | C19: 13.5 | D19: =C19-B19 -> -1.5 | E19: =D19/B19 -> -0.1 | F19: Développeur front Angular
A20: Sofia | B20: 23.5 | C20: 23.5 | D20: =C20-B20 -> 0 | E20: =D20/B20 -> 0 | F20: Développeuse back / DevOps
A21: Mateo | B21: 5 | C21: 4.5 | D21: =C21-B21 -> -0.5 | E21: =D21/B21 -> -0.1 | F21: UX designer freelance (Montréal)
A22: Camille | B22: 6 | C22: 7 | D22: =C22-B22 -> 1 | E22: =D22/B22 -> 0.16666667 | F22: Product Owner
A23: TOTAL | B23: =SUM(B18:B22) -> 72 | C23: =SUM(C18:C22) -> 74.5 | D23: =C23-B23 -> 2.5 | E23: =D23/B23 -> 0.034722222
A25: Taux d'occupation par sprint (réalisé ÷ capacité)
A26: Membre | B26: S0 | C26: S1 | D26: S2 | E26: S3 | F26: S4 | G26: S5 | H26: Alerte
A27: Raphaël | B27: 0.7 | C27: 0.13636364 | D27: 1.0833333 | E27: 1.25 | F27: 0.75 | G27: 0.1 | H27: =IF(MAX(B27:G27)>1,"Surcharge : "&TEXT(MAX(B27:G27),"0%")&" au pic","Charge maîtrisée") -> Surcharge : 125% au pic
A28: Hugo | B28: 0 | C28: 0.045454545 | D28: 1.0833333 | E28: 1 | F28: 0 | G28: 0 | H28: =IF(MAX(B28:G28)>1,"Surcharge : "&TEXT(MAX(B28:G28),"0%")&" au pic","Charge maîtrisée") -> Surcharge : 108% au pic
A29: Sofia | B29: 0.85 | C29: 0 | D29: 1.1666667 | E29: 1.0833333 | F29: 0 | G29: 0.3 | H29: =IF(MAX(B29:G29)>1,"Surcharge : "&TEXT(MAX(B29:G29),"0%")&" au pic","Charge maîtrisée") -> Surcharge : 117% au pic
A30: Mateo | B30: 0 | C30: 0.81818182 | D30: 0 | E30: 0 | F30: 0 | G30: 0 | H30: =IF(MAX(B30:G30)>1,"Surcharge : "&TEXT(MAX(B30:G30),"0%")&" au pic","Charge maîtrisée") -> Charge maîtrisée
A31: Camille | B31: 0.3 | C31: 0 | D31: 0.33333333 | E31: 1 | F31: 0.5 | G31: 0.4 | H31: =IF(MAX(B31:G31)>1,"Surcharge : "&TEXT(MAX(B31:G31),"0%")&" au pic","Charge maîtrisée") -> Charge maîtrisée
A32: Capacité = jours ouvrés du sprint × taux d'affectation au projet (1,0 pour les développeurs ; 0,5 PO ; 0,25 designer).
A34: Lecture : une valeur supérieure à 100 % signale un membre chargé au-delà de sa capacité sur le sprint.

Sheet Avancement
A1: Avancement : burn-up réel
A2: Charge cumulée livrée à chaque jalon, datée par les versions publiées (tags Git).
A4: Date | B4: Jalon | C4: Version | D4: Cumul livré (j/h) | E4: Cible finale (j/h) | F4: Avancement | G4: Contenu
A5: 2026-04-20 | B5: J0 · POC | C5: — | D5: 17 | E5: =Charge!$C$14 -> 74.5 | F5: =D5/E5 -> 0.22818792 | G5: Faisabilité technique validée : fournisseur musical et LLM retenus.
A6: 2026-06-19 | B6: J1 · Cadrage validé | C6: — | D6: 25.5 | E6: =Charge!$C$14 -> 74.5 | F6: =D6/E6 -> 0.34228188 | G6: Go du commanditaire sur le périmètre et le budget.
A7: 2026-07-14 | B7: J2 · MVP livré | C7: v0.2.0 | D7: 46.5 | E7: =Charge!$C$14 -> 74.5 | F7: =D7/E7 -> 0.62416107 | G7: Parcours complet cours → fiche → musique.
A8: 2026-07-22 | B8: J3 · Version durcie | C8: v1.0.0-rc.5 | D8: 69.5 | E8: =Charge!$C$14 -> 74.5 | F8: =D8/E8 -> 0.93288591 | G8: Sécurité, RGPD, tests, accessibilité, mise en production.
A9: 2026-07-24 | B9: J4 · Gel fonctionnel | C9: v1.0.0-rc.6 | D9: 71.5 | E9: =Charge!$C$14 -> 74.5 | F9: =D9/E9 -> 0.95973154 | G9: Périmètre V1 gelé.
A10: 2026-08-14 | B10: J5 · MCO | C10: v1.0.0-rc.7 | D10: 74.5 | E10: =Charge!$C$14 -> 74.5 | F10: =D10/E10 -> 1 | G10: Supervision et processus d'anomalies en place.
A12: Les dates et les versions proviennent des tags Git du dépôt. La charge est celle de l'équipe cible.
A14: Périmètre livré par priorité MoSCoW
A15: Priorité | B15: Éléments prévus | C15: Livrés | D15: Déprogrammés | E15: Taux de livraison | G15: Commentaire
A16: Must | B16: 42 | C16: 42 | D16: 0 | E16: =C16/B16 -> 1 | G16: Aucune concession : périmètre indispensable livré intégralement.
A17: Should | B17: 15 | C17: 13 | D17: 2 | E17: =C17/B17 -> 0.86666667 | G17: Deux éléments déprogrammés : paiement en ligne (reporté en v1.1) et file asynchrone locale (abandonnée).
A18: Could | B18: 6 | C18: 6 | D18: 0 | E18: =C18/B18 -> 1 | G18: Périmètre social livré au minimum utile, sans déprogrammation.
A19: TOTAL | B19: =SUM(B16:B18) -> 63 | C19: =SUM(C16:C18) -> 61 | D19: =SUM(D16:D18) -> 2 | E19: =C19/B19 -> 0.96825397 | G19: Hors anomalies et hors backlog v1.1.

Sheet Délais
A1: Délais : prévu vs réel
A2: Les jalons de restitution étaient imposés dès le lancement ; le planning a été construit à rebours.
A4: Jalon | B4: Prévu | C4: Réel | D4: Écart (j) | E4: Analyse
A5: J1 · Cadrage validé | B5: 2026-06-19 | C5: 2026-06-19 | D5: 0 | E5: Tenu.
A6: J2 · MVP livré | B6: 2026-05-29 | C6: 2026-07-14 | D6: 46 | E6: Conception prolongée d'un mois par la soutenance de cadrage, puis équipe mobilisée 2,5 semaines sur un projet client.
A7: J3 · Version durcie | B7: 2026-06-26 | C7: 2026-07-22 | D7: 26 | E7: Retard partiellement rattrapé par la réduction du périmètre (arbitrage de périmètre).
A8: J4 · Gel fonctionnel | B8: 2026-07-24 | C8: 2026-07-24 | D8: 0 | E8: Tenu : jalon non négociable, atteint grâce à l'arbitrage.
A9: J5 · MCO | B9: 2026-08-14 | C9: 2026-08-14 | D9: 0 | E9: Tenu.
A10: J6 · Recette et livraison | B10: 2026-09-16 | C10: en cours | E10: Sprint en cours.
A11: Jalons tenus à date | B11: =COUNT(D5:D10) -> 5 | C11: =COUNTIF(D5:D10,0) -> 3 | D11: =C11/B11 -> 0.6 | E11: Les deux jalons dépassés sont internes ; aucun jalon contractuel n'a été manqué.
A13: Cause racine du décalage J2 et J3
A14: • La préparation de la soutenance de cadrage a prolongé la phase de conception d'environ un mois.
A15: • L'équipe a ensuite été mobilisée deux semaines et demie sur un projet client prioritaire : 46 jours de décalage au total.
A16: • Conséquence : 2,5 semaines restantes pour un jalon non décalable, avec le front, la sécurité, la conformité et les tests à produire.
A17: • Décision : réduction du périmètre sur les priorités Should et Could, sans concession sur la qualité (voir la feuille Arbitrages).
A18: • Enseignement : le risque de disponibilité de l'équipe était identifié au cadrage mais n'était suivi par aucun indicateur.

Sheet Coûts
A1: Coûts : prévu vs réel
A2: Coûts d'exploitation uniquement. La main d'œuvre est valorisée séparément dans le budget projet.
A4: Exploitation mensuelle — volume actuel
A5: Poste | B5: Prévu (€/mois) | C5: Réel (€/mois) | D5: Écart | E5: Explication
A6: APIs IA — génération de texte | B6: =Données!$B$9 -> 80 | C6: =Données!$D$22 -> 0.01 | D6: =IF(B6=0,"",(C6-B6)/B6) -> -0.999875 | E6: Offre gratuite jusqu'au 14/09, puis facturation à l'usage : 0,01 € constaté.
A7: APIs IA — musique | B7: =Données!$B$10 -> 200 | C7: 0 | D7: =IF(B7=0,"",(C7-B7)/B7) -> -1 | E7: Un seul pack acheté sur toute la période ; le volume réel reste celui d'un service en recette.
A8: Infrastructure | B8: =Données!$B$11 -> 120 | C8: =Données!$D$19+Données!$D$20 -> 14.14 | D8: =IF(B8=0,"",(C8-B8)/B8) -> -0.88216667 | E8: Un VPS et un stockage objet ont suffi, au lieu d'une infrastructure cloud complète.
A9: Hébergement front | B9: =Données!$B$12 -> 20 | C9: =Données!$D$23 -> 0 | D9: =IF(B9=0,"",(C9-B9)/B9) -> -1 | E9: Arbitrage : front servi par le VPS, hébergement 100 % français.
A10: Outils et licences | B10: =Données!$B$13 -> 50 | C10: =Données!$D$21 -> 0.60833333 | D10: =IF(B10=0,"",(C10-B10)/B10) -> -0.98783333 | E10: Seul le nom de domaine est payant ; le reste repose sur des offres gratuites.
A11: TOTAL exploitation | B11: =SUM(B6:B10) -> 470 | C11: =SUM(C6:C10) -> 14.758333 | D11: =(C11-B11)/B11 -> -0.96859929 | E11: Le budget d'exploitation était très surdimensionné.
A13: Projection au volume cible du cadrage (500 générations/mois)
A14: Poste | B14: Prévu (€/mois) | C14: Projeté (€/mois) | D14: Écart | E14: Méthode de calcul
A15: APIs IA — musique | B15: =Données!$B$10 -> 200 | C15: =Données!$B$14*Données!$B$35*Données!$B$31 -> 27.6 | D15: =(C15-B15)/B15 -> -0.862 | E15: Volume cible × coût unitaire réel × taux de change.
A16: APIs IA — génération de texte | B16: =Données!$B$9 -> 80 | C16: =Données!$B$14*Données!$D$22/Données!$B$33*Données!$B$34 -> 1 | D16: =(C16-B16)/B16 -> -0.9875 | E16: Volume cible × coût unitaire constaté, doublé par prudence.
A17: Autres postes | B17: =B11-B7-B6 -> 190 | C17: =C11-C7-C6 -> 14.748333 | D17: =(C17-B17)/B17 -> -0.92237719 | E17: Coûts fixes : inchangés à ce volume.
A18: TOTAL au volume cible | B18: =SUM(B15:B17) -> 470 | C18: =SUM(C15:C17) -> 43.348333 | D18: =(C18-B18)/B18 -> -0.9077695 | E18: Même au volume nominal, le budget restait surestimé d'un ordre de grandeur.
A20: Coût variable par génération — indépendant du volume
A21: Composant | B21: Coût unitaire | C21: Fiabilité | E21: Base de calcul
A22: Génération musicale | B22: =Données!$B$35*Données!$B$31 -> 0.0552 | C22: Élevée | E22: Tarif fixe : 12 tokens par titre, indépendant du contenu.
A23: Génération de texte (marge incluse) | B23: =Données!$D$22/Données!$B$33*Données!$B$34 -> 0.002 | C23: Ordre de grandeur | E23: Dépend de la longueur du cours : relevé sur 10 générations, doublé par prudence.
A24: TOTAL par génération | B24: =SUM(B22:B23) -> 0.0572 | E24: Seuil de rentabilité : un abonné premium couvre son coût dès la première génération.
A26: Effet sur le modèle économique
A27: Indicateur | B27: Cadrage | C27: Réel | E27: Commentaire
A28: Coût d'appel IA par génération | B28: 0.4 | C28: =Données!$B$35*Données!$B$31 -> 0.0552 | E28: Le cadrage déduisait 0,40 € de la ligne budgétaire (200 € ÷ 500 générations), sans consulter la grille tarifaire du fournisseur.
A29: Coût mensuel d'un abonné premium | C29: =Données!$B$32*Coûts!$B$24 -> 1.144 | E29: 20 générations par mois et par abonné, au coût unitaire complet ci-dessus.
A30: Marge brute par abonné | B30: 0.5 | C30: =(Données!$B$15-C29)/Données!$B$15 -> 0.77074148 | E30: L'erreur d'estimation du coût unitaire sous-évaluait la marge du modèle freemium.
A32: Réserve : ces montants ne couvrent ni la main d'œuvre, ni le support, ni la conformité (délégué à la protection des données), qui deviennent les postes dominants à l'échelle.

Sheet Risques
A1: Registre des risques
A2: Criticité = probabilité × impact, sur une échelle de 1 à 4. Mise à jour au 11/09/2026.
A4: Risque | B4: Prob. | C4: Impact | D4: Criticité | E4: Mesure prise | F4: Statut à date
A5: Dépendance aux fournisseurs d'IA | B5: 3 | C5: 4 | D5: =B5*C5 -> 12 | E5: Interface d'abstraction côté musique ; modèle de langage rendu configurable par variable d'environnement. | F5: Survenu le 14/09 côté texte (refus du modèle par le palier d'abonnement) — corrigé en 24 h.
A6: Disponibilité de l'équipe en période chargée | B6: 4 | C6: 4 | D6: =B6*C6 -> 16 | E6: Aucune mesure de suivi au moment des faits. | F6: Survenu — décalage de 7 semaines ; suivi hebdomadaire de la capacité mis en place.
A7: Coût des appels IA supérieur au budget | B7: 2 | C7: 3 | D7: =B7*C7 -> 6 | E7: Cache anti-redondance et quota mensuel par utilisateur. | F7: Écarté — coût réel très inférieur au budget.
A8: Non-conformité RGPD sur un public mineur | B8: 2 | C8: 4 | D8: =B8*C8 -> 8 | E8: Contrôle d'âge, consentement parental sous 15 ans, effacement en cascade, information sur les transferts hors UE. | F8: Maîtrisé — réserve sur la vérification par email du responsable légal.
A9: Contenu inapproprié généré par l'IA | B9: 3 | C9: 4 | D9: =B9*C9 -> 12 | E9: Modération des contenus soumis avant tout appel (refus en cas d'indisponibilité). | F9: Partiellement couvert — modération des contenus générés inscrite en v1.1.
A10: Perte de résultat de génération (webhook) | B10: 3 | C10: 3 | D10: =B10*C10 -> 9 | E10: Point de rattrapage et interrogation périodique du statut. | F10: Maîtrisé — anomalies B-03 et B-04 corrigées.
A11: Indisponibilité de la production | B11: 2 | C11: 3 | D11: =B11*C11 -> 6 | E11: Sondes de santé, politique de redémarrage, supervision externe avec alerte. | F11: Maîtrisé — mesure livrée.
A12: Dette technique sur les dépendances | B12: 2 | C12: 2 | D12: =B12*C12 -> 4 | E12: Veille automatisée et audit de sécurité en intégration continue. | F12: Suivi — montée de version majeure du front inscrite en v1.1.
A13: Une seule personne maîtrise le déploiement | B13: 4 | C13: 3 | D13: =B13*C13 -> 12 | E13: Documentation de déploiement, d'utilisation et de mise à jour ; décisions d'architecture consignées. | F13: Résiduel — revue par un pair recommandée.
A15: Criticité moyenne | D15: =AVERAGE(D5:D13) -> 9.4444444 | E15: Risques à criticité ≥ 12 | F15: =COUNTIF(D5:D13,">=12") -> 4
A17: Le risque de disponibilité de l'équipe s'est réalisé. Il figurait au registre de cadrage, mais aucun indicateur ne le surveillait : c'est le principal enseignement de pilotage du projet.

Sheet Arbitrages
A1: Arbitrages de périmètre
A2: Décisions prises en comité de pilotage, tracées dans l'outil de suivi (tickets déprogrammés) et dans le journal des décisions.
A4: Sujet | B4: Problème | C4: Options étudiées | D4: Décision | E4: Conséquence mesurée
A5: File asynchrone (S2) | B5: La génération musicale est longue et le jalon MVP est proche. | C5: A : file de traitement locale · B : délégation au fournisseur via rappel HTTP | D5: B — rappel HTTP du fournisseur, complété par un point de rattrapage. | E5: 2 j/h économisés. Effet de bord : anomalies B-03 et B-04, corrigées dans le sprint.
A6: Paiement en ligne (S3) | B6: 2,5 semaines avant un jalon non décalable, avec la sécurité, la conformité et les tests à produire. | C6: A : décaler le jalon · B : renforcer l'équipe · C : réduire le périmètre · D : réduire la qualité | D6: C — paiement simulé, modèle de données conservé ; exigences de qualité préservées. | E6: 100 % des priorités Must livrées. Reprogrammé en v1.1 (6,5 j/h).
A7: Hébergement du front (S3) | B7: Le budget prévoyait un hébergement front dédié en offre payante. | C7: A : offre payante dédiée · B : service assuré par le VPS existant | D7: B — front servi par le VPS, hébergement 100 % français. | E7: 20 €/mois économisés et cohérence avec l'engagement bas carbone.
A8: Fournisseur de LLM (S0) | B8: Deux fournisseurs candidats pour la fiche et les paroles. | C8: A : fournisseur n° 1 · B : fournisseur n° 2 | D8: B — meilleur rapport qualité/coût sur les cours testés ; module concurrent retiré. | E8: Coût des appels de génération de texte nul à ce jour.
A10: Règle d'arbitrage appliquée : la qualité et la conformité ne sont jamais la variable d'ajustement ; le périmètre Should et Could l'est.

Sheet Qualité
A1: Qualité et satisfaction
A2: Les indicateurs de qualité sont mesurés. Les indicateurs de satisfaction sont définis, avec leur méthode de collecte ; ils ne sont pas encore mesurés.
A4: Qualité — mesuré
A5: Indicateur | B5: Valeur | C5: Cible | D5: Atteint | E5: Source
A6: Cas de test automatisés | B6: =Données!$B$39+Données!$B$40+Données!$B$41 -> 177 | C6: 150 | D6: =IF(B6>=C6,"Oui","Non") -> Oui | E6: Suites de tests du dépôt
A7: Couverture — instructions (seuil bloquant) | B7: =Données!$B$42 -> 0.81 | C7: 0.8 | D7: =IF(B7>=C7,"Oui","Non") -> Oui | E7: Configuration de couverture, bloquante en intégration continue
A8: Couverture — branches (seuil bloquant) | B8: =Données!$B$43 -> 0.63 | C8: 0.6 | D8: =IF(B8>=C8,"Oui","Non") -> Oui | E8: Configuration de couverture, bloquante en intégration continue
A9: Scénarios de recette exécutés | B9: =Données!$B$44 -> 37 | C9: 30 | D9: =IF(B9>=C9,"Oui","Non") -> Oui | E9: Cahier de recettes
A10: Anomalies corrigées | B10: =Données!$B$45 -> 10 | C10: 10 | D10: =IF(B10>=C10,"Oui","Non") -> Oui | E10: Plan de correction des anomalies
A11: Anomalies ouvertes | B11: =Données!$B$46 -> 0 | C11: 0 | D11: =IF(B11<=C11,"Oui","Non") -> Oui | E11: Plan de correction des anomalies
A12: Taux de cibles qualité atteintes | B12: =COUNTIF(D6:D11,"Oui") -> 6 | C12: =11-6+1 -> 6 | D12: =B12/C12 -> 1
A14: Satisfaction — défini, non encore mesuré
A15: Indicateur | B15: Cible | C15: Fréquence | D15: Statut | E15: Méthode de collecte
A16: Score SUS (utilisabilité perçue) | B16: ≥ 70/100 | C16: À chaque version majeure | D16: À collecter | E16: Questionnaire SUS de 10 items auprès d'un panel d'élèves.
A17: Taux de génération aboutie | B17: ≥ 95 % | C17: Hebdomadaire | D17: Calculable | E17: Part des générations en statut terminé sur l'ensemble des générations.
A18: Taux de mise en favori | B18: ≥ 25 % | C18: Mensuelle | D18: Calculable | E18: Titres mis en favori rapportés aux titres générés — signal de valeur perçue.
A19: Satisfaction du commanditaire | B19: ≥ 4/5 | C19: À chaque comité de pilotage | D19: À collecter | E19: Question unique en fin de comité de pilotage.
A20: Délai de traitement d'une anomalie | B20: < 5 jours | C20: Mensuelle | D20: Mesurable | E20: Écart entre la détection et la livraison du correctif.
A22: Premier signal qualitatif : trois testeurs ont utilisé la génération sans blocage fonctionnel. L'échantillon est trop restreint pour produire un indicateur chiffré.
